//  A wrapper for catching errors and also eliminate the use of try.Catch block globally
const catchAsync = (fn) => (req, res, next) => {
  Promise.resolve(fn(req, res, next)).catch((err) => next(err));
};

module.exports = catchAsync;
